<sdf version='1.7'>
  <model name='wheel_biped'>
    <link name='base_Link'>
      <inertial>
        <pose>0.04576 0.00014 -0.16398 0 -0 0</pose>
        <mass>9.585</mass>
        <inertia>
          <ixx>0.14011</ixx>
          <ixy>0.000534939</ixy>
          <ixz>0.0281841</ixz>
          <iyy>0.110641</iyy>
          <iyz>-2.7278e-05</iyz>
          <izz>0.0989445</izz>
        </inertia>
      </inertial>
      <collision name='base_Link_collision'>
        <pose>0.03 0 -0.072 0 -0 0</pose>
        <geometry>
          <box>
            <size>0.27 0.26 0.19</size>
          </box>
        </geometry>
      </collision>
      <visual name='base_Link_visual'>
        <pose>0 0 0 0 -0 0</pose>
        <geometry>
          <mesh>
            <scale>1 1 1</scale>
            <uri>model://WF_TRON1A/meshes/base_Link.STL</uri>
          </mesh>
        </geometry>
      </visual>
    </link>
    <include>
        <uri>model://D435i</uri>
        <pose>0.139465 0.0047 -0.281286 2.63457 0 1.5708</pose>
        <name>D435i</name>
    </include>
    <joint name="d435i_joint" type="fixed">
        <parent>base_Link</parent>
        <child>D435i::camera_link</child>
        <pose>0.13223 0.0047 -0.26826 0 1.06378 0</pose>
    </joint>

    <link name = "lidar_Link">
      <pose>0.0 0.0 0.05 0.0 0.0 0.0</pose>
      <inertial>
        <mass>0.1</mass>
        <inertia>
          <ixx>0.0001</ixx>
          <ixy>0.0</ixy>
          <ixz>0.0</ixz>
          <iyy>0.0001</iyy>
          <iyz>0.0</iyz>
          <izz>0.0001</izz>
        </inertia>
      </inertial>
      <collision name = "lidar_collision">
        <geometry>
          <box>
            <size>0.05 0.05 0.05</size>
          </box>
        </geometry>
      </collision>
      <visual name='lidar_visual'>
        <pose>0 0 0 0 -0 0</pose>
        <geometry>
          <mesh>
            <scale>1 1 1</scale>
            <uri>model://livox/livox_mid-360-90x.dae</uri>
          </mesh>
        </geometry>
      </visual>

      <sensor type="ray" name="laser_livox">
        <pose>0 0 0.05 0 0 0</pose>
        <visualize>true</visualize>
        <always_on>True</always_on>
        <update_rate>10</update_rate>
        <!-- This ray plgin is only for visualization. -->
        <plugin name="gazebo_ros_laser_controller" filename="liblivox_laser_simulation.so">
			  <ray>
			  <scan>
				  <horizontal>
				    <samples>100</samples>
				    <resolution>1</resolution>
				    <min_angle>-3.1415926535897931</min_angle>
            <max_angle>3.1415926535897931</max_angle>
				  </horizontal>
				  <vertical>
				    <samples>50</samples>
				    <resolution>1</resolution>
				    <min_angle>-3.1415926535897931</min_angle>
            <max_angle>3.1415926535897931</max_angle>
				  </vertical>
			  </scan>
			  <range>
				  <min>0.1</min>
				  <max>40</max>
				  <resolution>1</resolution>
			  </range>
			  <noise>
				  <type>gaussian</type>
				  <mean>0.0</mean>
				  <stddev>0.0</stddev>
			  </noise>
			  </ray>
          <visualize>True</visualize>
		      <samples>20000</samples>
		      <downsample>1</downsample>
		      <csv_file_name>mid360-real-centr.csv</csv_file_name>
          <publish_pointcloud_type>2</publish_pointcloud_type>
		      <ros_topic>/livox/lidar</ros_topic>
          <frameName>base_link</frameName>
        </plugin>
      </sensor>

    </link>

    <joint name="lidar_joint" type="fixed">
      <parent>base_Link</parent>
      <child>lidar_Link</child>
      <pose>0 0 0.05 0 0 0</pose>
    </joint>

    <joint name='abad_L_Joint' type='revolute'>
      <pose relative_to='base_Link'>0.05556 0.105 -0.2602 0 -0 0</pose>
      <parent>base_Link</parent>
      <child>abad_L_Link</child>
      <axis>
        <xyz>1 0 0</xyz>
        <limit>
          <lower>-0.38397</lower>
          <upper>1.39626</upper>
          <effort>80</effort>
          <velocity>15</velocity>
        </limit>
        <dynamics>
          <spring_reference>0</spring_reference>
          <spring_stiffness>0</spring_stiffness>
        </dynamics>
      </axis>
    </joint>
    <link name='abad_L_Link'>
      <pose relative_to='abad_L_Joint'>0 0 0 0 -0 0</pose>
      <inertial>
        <pose>-0.06977 0.04479 0.00057 0 -0 0</pose>
        <mass>1.469</mass>
        <inertia>
          <ixx>0.00155538</ixx>
          <ixy>0.00039778</ixy>
          <ixz>-1.31e-05</ixz>
          <iyy>0.00235925</iyy>
          <iyz>-9.8e-07</iyz>
          <izz>0.00208092</izz>
        </inertia>
      </inertial>
      <collision name='abad_L_Link_collision'>
        <pose>0.03 0 0 1.57 -0 1.57</pose>
        <geometry>
          <cylinder>
            <length>0.05</length>
            <radius>0.05</radius>
          </cylinder>
        </geometry>
      </collision>
      <visual name='abad_L_Link_visual'>
        <pose>0 0 0 0 -0 0</pose>
        <geometry>
          <mesh>
            <scale>1 1 1</scale>
            <uri>model://WF_TRON1A/meshes/abad_L_Link.STL</uri>
          </mesh>
        </geometry>
      </visual>
    </link>
    <joint name='hip_L_Joint' type='revolute'>
      <pose relative_to='abad_L_Link'>-0.077 0.0205 0 0 -0 0</pose>
      <parent>abad_L_Link</parent>
      <child>hip_L_Link</child>
      <axis>
        <xyz>0 1 0</xyz>
        <limit>
          <lower>-1.01229</lower>
          <upper>1.39626</upper>
          <effort>80</effort>
          <velocity>15</velocity>
        </limit>
        <dynamics>
          <spring_reference>0</spring_reference>
          <spring_stiffness>0</spring_stiffness>
        </dynamics>
      </axis>
    </joint>
    <link name='hip_L_Link'>
      <pose relative_to='hip_L_Joint'>0 0 0 0 -0 0</pose>
      <inertial>
        <pose>-0.02869 -0.0477 -0.03992 0 -0 0</pose>
        <mass>2.3</mass>
        <inertia>
          <ixx>0.0169373</ixx>
          <ixy>0.00164703</ixy>
          <ixz>-0.00923253</ixz>
          <iyy>0.0228533</iyy>
          <iyz>0.0022024</iyz>
          <izz>0.00933419</izz>
        </inertia>
      </inertial>
      <collision name='hip_L_Link_collision'>
        <pose>-0.1 -0.03 -0.14 0 0.53 0</pose>
        <geometry>
          <cylinder>
            <length>0.15</length>
            <radius>0.035</radius>
          </cylinder>
        </geometry>
        <surface>
          <contact>
            <ode/>
          </contact>
          <friction>
            <ode>
              <mu>0.2</mu>
              <mu2>0.2</mu2>
            </ode>
          </friction>
        </surface>
      </collision>
      <visual name='hip_L_Link_visual'>
        <pose>0 0 0 0 -0 0</pose>
        <geometry>
          <mesh>
            <scale>1 1 1</scale>
            <uri>model://WF_TRON1A/meshes/hip_L_Link.STL</uri>
          </mesh>
        </geometry>
        <material>
          <script>
            <name>Gazebo/DarkGrey</name>
            <uri>file://media/materials/scripts/gazebo.material</uri>
          </script>
        </material>
      </visual>
    </link>
    <joint name='knee_L_Joint' type='revolute'>
      <pose relative_to='hip_L_Link'>-0.15 -0.0205 -0.25981 0 -0 0</pose>
      <parent>hip_L_Link</parent>
      <child>knee_L_Link</child>
      <axis>
        <xyz>0 -1 0</xyz>
        <limit>
          <lower>-0.872665</lower>
          <upper>1.36136</upper>
          <effort>80</effort>
          <velocity>15</velocity>
        </limit>
        <dynamics>
          <spring_reference>0</spring_reference>
          <spring_stiffness>0</spring_stiffness>
        </dynamics>
      </axis>
    </joint>
    <link name='knee_L_Link'>
      <pose relative_to='knee_L_Joint'>0 0 0 0 -0 0</pose>
      <inertial>
        <pose>0.11913 0.01106 -0.20363 0 -0 0</pose>
        <mass>1.49</mass>
        <inertia>
          <ixx>0.0132328</ixx>
          <ixy>-0.00043546</ixy>
          <ixz>0.00693569</ixz>
          <iyy>0.0176614</iyy>
          <iyz>0.00079087</iyz>
          <izz>0.00501698</izz>
        </inertia>
      </inertial>
      <collision name='knee_L_Link_collision'>
        <pose>0.078 0 -0.12 0 -0.55 0</pose>
        <geometry>
          <cylinder>
            <length>0.26</length>
            <radius>0.015</radius>
          </cylinder>
        </geometry>
        <surface>
          <contact>
            <ode>
              <kp>1e+06</kp>
              <kd>100</kd>
            </ode>
          </contact>
          <friction>
            <ode>
              <mu>0.2</mu>
              <mu2>0.2</mu2>
            </ode>
          </friction>
        </surface>
      </collision>
      <visual name='knee_L_Link_visual'>
        <pose>0 0 0 0 -0 0</pose>
        <geometry>
          <mesh>
            <scale>1 1 1</scale>
            <uri>model://WF_TRON1A/meshes/knee_L_Link.STL</uri>
          </mesh>
        </geometry>
        <material>
          <script>
            <name>Gazebo/DarkGrey</name>
            <uri>file://media/materials/scripts/gazebo.material</uri>
          </script>
        </material>
      </visual>
      <self_collide>0</self_collide>
    </link>
    <joint name='wheel_L_Joint' type='revolute'>
      <pose relative_to='knee_L_Link'>0.15 0.0435 -0.25981 0 -0 0</pose>
      <parent>knee_L_Link</parent>
      <child>wheel_L_Link</child>
      <axis>
        <xyz>0 1 0</xyz>
        <limit>
          <lower>-1e+06</lower>
          <upper>1e+06</upper>
          <effort>40</effort>
          <velocity>40</velocity>
        </limit>
        <dynamics>
          <damping>0</damping>
          <friction>0.01</friction>
          <spring_reference>0</spring_reference>
          <spring_stiffness>0</spring_stiffness>
        </dynamics>
      </axis>
    </joint>
    <link name='wheel_L_Link'>
      <pose relative_to='wheel_L_Joint'>0 0 0 0 -0 0</pose>
      <inertial>
        <pose>3e-05 0.00807 -2e-05 0 -0 0</pose>
        <mass>1.08</mass>
        <inertia>
          <ixx>0.00515512</ixx>
          <ixy>1e-08</ixy>
          <ixz>-9.7e-07</ixz>
          <iyy>0.00974272</iyy>
          <iyz>-1e-08</iyz>
          <izz>0.005154</izz>
        </inertia>
      </inertial>
      <collision name='wheel_L_Link_collision'>
        <pose>0 0 0 1.5708 -0 0</pose>
        <geometry>
          <cylinder>
            <length>0.05</length>
            <radius>0.127</radius>
          </cylinder>
        </geometry>
        <surface>
          <contact>
            <ode>
              <kp>1e+06</kp>
              <kd>1</kd>
            </ode>
          </contact>
          <friction>
            <ode>
              <mu>0.6</mu>
              <mu2>0.6</mu2>
            </ode>
          </friction>
        </surface>
      </collision>
      <visual name='wheel_L_Link_visual'>
        <pose>0 0 0 0 -0 0</pose>
        <geometry>
          <mesh>
            <scale>1 1 1</scale>
            <uri>model://WF_TRON1A/meshes/wheel_L_Link.STL</uri>
          </mesh>
        </geometry>
        <material>
          <script>
            <name>Gazebo/DarkGrey</name>
            <uri>file://media/materials/scripts/gazebo.material</uri>
          </script>
        </material>
      </visual>
      <self_collide>1</self_collide>
    </link>
    <joint name='abad_R_Joint' type='revolute'>
      <pose relative_to='base_Link'>0.05556 -0.105 -0.2602 0 -0 0</pose>
      <parent>base_Link</parent>
      <child>abad_R_Link</child>
      <axis>
        <xyz>1 0 0</xyz>
        <limit>
          <lower>-1.39626</lower>
          <upper>0.38397</upper>
          <effort>80</effort>
          <velocity>15</velocity>
        </limit>
        <dynamics>
          <spring_reference>0</spring_reference>
          <spring_stiffness>0</spring_stiffness>
        </dynamics>
      </axis>
    </joint>
    <link name='abad_R_Link'>
      <pose relative_to='abad_R_Joint'>0 0 0 0 -0 0</pose>
      <inertial>
        <pose>-0.06977 -0.04479 0.00057 0 -0 0</pose>
        <mass>1.469</mass>
        <inertia>
          <ixx>0.00155538</ixx>
          <ixy>-0.00039778</ixy>
          <ixz>-1.31e-05</ixz>
          <iyy>0.00235925</iyy>
          <iyz>9.8e-07</iyz>
          <izz>0.00208092</izz>
        </inertia>
      </inertial>
      <collision name='abad_R_Link_collision'>
        <pose>0.03 0 0 1.57 -0 1.57</pose>
        <geometry>
          <cylinder>
            <length>0.05</length>
            <radius>0.05</radius>
          </cylinder>
        </geometry>
      </collision>
      <visual name='abad_R_Link_visual'>
        <pose>0 0 0 0 -0 0</pose>
        <geometry>
          <mesh>
            <scale>1 1 1</scale>
            <uri>model://WF_TRON1A/meshes/abad_R_Link.STL</uri>
          </mesh>
        </geometry>
      </visual>
    </link>
    <joint name='hip_R_Joint' type='revolute'>
      <pose relative_to='abad_R_Link'>-0.077 -0.0205 0 0 -0 0</pose>
      <parent>abad_R_Link</parent>
      <child>hip_R_Link</child>
      <axis>
        <xyz>0 -1 0</xyz>
        <limit>
          <lower>-1.39626</lower>
          <upper>1.01229</upper>
          <effort>80</effort>
          <velocity>15</velocity>
        </limit>
        <dynamics>
          <spring_reference>0</spring_reference>
          <spring_stiffness>0</spring_stiffness>
        </dynamics>
      </axis>
    </joint>
    <link name='hip_R_Link'>
      <pose relative_to='hip_R_Joint'>0 0 0 0 -0 0</pose>
      <inertial>
        <pose>-0.02869 0.0477 -0.03992 0 -0 0</pose>
        <mass>2.3</mass>
        <inertia>
          <ixx>0.0169373</ixx>
          <ixy>-0.00164703</ixy>
          <ixz>-0.00923253</ixz>
          <iyy>0.0228533</iyy>
          <iyz>-0.0022024</iyz>
          <izz>0.00933419</izz>
        </inertia>
      </inertial>
      <collision name='hip_R_Link_collision'>
        <pose>-0.1 0.03 -0.14 0 0.53 0</pose>
        <geometry>
          <cylinder>
            <length>0.15</length>
            <radius>0.035</radius>
          </cylinder>
        </geometry>
        <surface>
          <contact>
            <ode/>
          </contact>
          <friction>
            <ode>
              <mu>0.2</mu>
              <mu2>0.2</mu2>
            </ode>
          </friction>
        </surface>
      </collision>
      <visual name='hip_R_Link_visual'>
        <pose>0 0 0 0 -0 0</pose>
        <geometry>
          <mesh>
            <scale>1 1 1</scale>
            <uri>model://WF_TRON1A/meshes/hip_R_Link.STL</uri>
          </mesh>
        </geometry>
        <material>
          <script>
            <name>Gazebo/DarkGrey</name>
            <uri>file://media/materials/scripts/gazebo.material</uri>
          </script>
        </material>
      </visual>
    </link>
    <joint name='knee_R_Joint' type='revolute'>
      <pose relative_to='hip_R_Link'>-0.15 0.0205 -0.25981 0 -0 0</pose>
      <parent>hip_R_Link</parent>
      <child>knee_R_Link</child>
      <axis>
        <xyz>0 1 0</xyz>
        <limit>
          <lower>-1.36136</lower>
          <upper>0.872665</upper>
          <effort>80</effort>
          <velocity>15</velocity>
        </limit>
        <dynamics>
          <spring_reference>0</spring_reference>
          <spring_stiffness>0</spring_stiffness>
        </dynamics>
      </axis>
    </joint>
    <link name='knee_R_Link'>
      <pose relative_to='knee_R_Joint'>0 0 0 0 -0 0</pose>
      <inertial>
        <pose>0.11913 -0.01106 -0.20363 0 -0 0</pose>
        <mass>1.49</mass>
        <inertia>
          <ixx>0.0132328</ixx>
          <ixy>0.00043546</ixy>
          <ixz>0.00693569</ixz>
          <iyy>0.0176614</iyy>
          <iyz>-0.00079087</iyz>
          <izz>0.00501698</izz>
        </inertia>
      </inertial>
      <collision name='knee_R_Link_collision'>
        <pose>0.078 0 -0.12 0 -0.55 0</pose>
        <geometry>
          <cylinder>
            <length>0.26</length>
            <radius>0.015</radius>
          </cylinder>
        </geometry>
        <surface>
          <contact>
            <ode>
              <kp>1e+06</kp>
              <kd>100</kd>
            </ode>
          </contact>
          <friction>
            <ode>
              <mu>0.2</mu>
              <mu2>0.2</mu2>
            </ode>
          </friction>
        </surface>
      </collision>
      <visual name='knee_R_Link_visual'>
        <pose>0 0 0 0 -0 0</pose>
        <geometry>
          <mesh>
            <scale>1 1 1</scale>
            <uri>model://WF_TRON1A/meshes/knee_R_Link.STL</uri>
          </mesh>
        </geometry>
        <material>
          <script>
            <name>Gazebo/DarkGrey</name>
            <uri>file://media/materials/scripts/gazebo.material</uri>
          </script>
        </material>
      </visual>
      <self_collide>0</self_collide>
    </link>
    <joint name='wheel_R_Joint' type='revolute'>
      <pose relative_to='knee_R_Link'>0.15 -0.0435 -0.25981 0 -0 0</pose>
      <parent>knee_R_Link</parent>
      <child>wheel_R_Link</child>
      <axis>
        <xyz>0 1 0</xyz>
        <limit>
          <lower>-1e+06</lower>
          <upper>1e+06</upper>
          <effort>40</effort>
          <velocity>40</velocity>
        </limit>
        <dynamics>
          <damping>0</damping>
          <friction>0.01</friction>
          <spring_reference>0</spring_reference>
          <spring_stiffness>0</spring_stiffness>
        </dynamics>
      </axis>
    </joint>
    <link name='wheel_R_Link'>
      <pose relative_to='wheel_R_Joint'>0 0 0 0 -0 0</pose>
      <inertial>
        <pose>3e-05 -0.00807 -2e-05 0 -0 0</pose>
        <mass>1.08</mass>
        <inertia>
          <ixx>0.00515512</ixx>
          <ixy>-1e-08</ixy>
          <ixz>-9.7e-07</ixz>
          <iyy>0.00974272</iyy>
          <iyz>1e-08</iyz>
          <izz>0.005154</izz>
        </inertia>
      </inertial>
      <collision name='wheel_R_Link_collision'>
        <pose>0 0 0 1.5708 -0 0</pose>
        <geometry>
          <cylinder>
            <length>0.05</length>
            <radius>0.127</radius>
          </cylinder>
        </geometry>
        <surface>
          <contact>
            <ode>
              <kp>1e+06</kp>
              <kd>1</kd>
            </ode>
          </contact>
          <friction>
            <ode>
              <mu>0.6</mu>
              <mu2>0.6</mu2>
            </ode>
          </friction>
        </surface>
      </collision>
      <visual name='wheel_R_Link_visual'>
        <pose>0 0 0 0 -0 0</pose>
        <geometry>
          <mesh>
            <scale>1 1 1</scale>
            <uri>model://WF_TRON1A/meshes/wheel_R_Link.STL</uri>
          </mesh>
        </geometry>
        <material>
          <script>
            <name>Gazebo/DarkGrey</name>
            <uri>file://media/materials/scripts/gazebo.material</uri>
          </script>
        </material>
      </visual>
      <self_collide>1</self_collide>
    </link>
    <joint name='limx_imu_joint' type='revolute'>
      <pose relative_to='base_Link'>0 0 0 0 -0 0</pose>
      <parent>base_Link</parent>
      <child>limx_imu</child>
      <axis>
        <limit>
          <lower>0</lower>
          <upper>0</upper>
        </limit>
        <dynamics>
          <damping>0</damping>
          <friction>0</friction>
          <spring_reference>0</spring_reference>
          <spring_stiffness>0</spring_stiffness>
        </dynamics>
        <xyz>0 0 1</xyz>
      </axis>
      <physics>
        <ode>
          <limit>
            <cfm>0</cfm>
            <erp>0.2</erp>
          </limit>
        </ode>
      </physics>
    </joint>
    <link name='limx_imu'>
      <pose relative_to='limx_imu_joint'>0 0 0 0 -0 0</pose>
      <inertial>
        <pose>0 0 0 0 -0 0</pose>
        <mass>0.01</mass>
        <inertia>
          <ixx>1e-06</ixx>
          <ixy>0</ixy>
          <ixz>0</ixz>
          <iyy>1e-06</iyy>
          <iyz>0</iyz>
          <izz>1e-06</izz>
        </inertia>
      </inertial>
      <visual name='limx_imu_visual'>
        <pose>0 0 0 0 -0 0</pose>
        <geometry>
          <box>
            <size>0.015 0.015 0.004</size>
          </box>
        </geometry>
        <material>
          <script>
            <name>Gazebo/Orange</name>
            <uri>file://media/materials/scripts/gazebo.material</uri>
          </script>
        </material>
      </visual>
    </link>

    <plugin name='gazebo_ros_control' filename='libpointfoot_hw_sim.so'>
      <robotNamespace>/</robotNamespace>
      <robotParam>robot_description</robotParam>
      <robotSimType>pointfoot_gazebo/PointFootHWSim</robotSimType>
    </plugin>
    <static>0</static>
    <plugin name='p3d_base_controller' filename='libgazebo_ros_p3d.so'>
      <alwaysOn>1</alwaysOn>
      <updateRate>1000.0</updateRate>
      <bodyName>base_Link</bodyName>
      <topicName>ground_truth/state</topicName>
      <gaussianNoise>0</gaussianNoise>
      <frameName>world</frameName>
      <xyzOffsets>0 0 0</xyzOffsets>
      <rpyOffsets>0 0 0</rpyOffsets>
    </plugin>
  </model>
</sdf>
